Workbook

Sheet all_feats_500ns
A1: name | B1: ID | C1: Group | D1: Label | E1: Binder_score | F1: Sequence | G1: Gate (r84-90) mean (A) | H1: Gate (r84-90) SD (A) | I1: Gate RMSD late100 mean (A) | J1: Latch RMSD late100 mean (A) | K1: mean_n_polar | L1: std_n_polar | M1: mean_n_pos_charged | N1: std_n_pos_charged | O1: mean_n_neg_charged | P1: std_n_neg_charged | Q1: Y23 RMSF (A) | R1: R79 RMSF (A) | S1: I110 RMSF (A) | T1: G163 RMSF (A) | U1: D_28 | V1: W_28 | W1: D_30 | X1: W_30 | Y1: D_32 | Z1: W_32 | AA1: D_33 | AB1: W_33 | AC1: D_34 | AD1: W_34 | AE1: D_35 | AF1: W_35 | AG1: D_36 | AH1: W_36 | AI1: D_46 | AJ1: W_46 | AK1: D_48 | AL1: W_48 | AM1: D_49 | AN1: W_49 | AO1: D_50 | AP1: W_50 | AQ1: D_51 | AR1: W_51 | AS1: D_52 | AT1: W_52 | AU1: D_53 | AV1: W_53 | AW1: D_54 | AX1: W_54 | AY1: D_55 | AZ1: W_55 | BA1: D_56 | BB1: W_56 | BC1: D_57 | BD1: W_57 | BE1: D_58 | BF1: W_58 | BG1: D_59 | BH1: W_59 | BI1: D_60 | BJ1: W_60 | BK1: D_61 | BL1: W_61 | BM1: D_62 | BN1: W_62 | BO1: D_64 | BP1: W_64 | BQ1: D_65 | BR1: W_65 | BS1: D_66 | BT1: W_66 | BU1: D_67 | BV1: W_67 | BW1: D_69 | BX1: W_69 | BY1: D_71 | BZ1: W_71 | CA1: D_73 | CB1: W_73 | CC1: D_76 | CD1: W_76 | CE1: D_77 | CF1: W_77 | CG1: D_78 | CH1: W_78 | CI1: D_79 | CJ1: W_79 | CK1: D_80 | CL1: W_80 | CM1: D_81 | CN1: W_81 | CO1: D_82 | CP1: W_82 | CQ1: D_83 | CR1: W_83 | CS1: D_84 | CT1: W_84 | CU1: D_85 | CV1: W_85 | CW1: D_86 | CX1: W_86 | CY1: D_87 | CZ1: W_87 | DA1: D_88 | DB1: W_88 | DC1: D_89 | DD1: W_89 | DE1: D_90 | DF1: W_90 | DG1: D_91 | DH1: W_91 | DI1: D_92 | DJ1: W_92 | DK1: D_93 | DL1: W_93 | DM1: D_94 | DN1: W_94 | DO1: D_95 | DP1: W_95 | DQ1: D_96 | DR1: W_96 | DS1: D_97 | DT1: W_97 | DU1: D_98 | DV1: W_98 | DW1: D_99 | DX1: W_99 | DY1: D_105 | DZ1: W_105 | EA1: D_106 | EB1: W_106 | EC1: D_107 | ED1: W_107 | EE1: D_108 | EF1: W_108 | EG1: D_109 | EH1: W_109 | EI1: D_110 | EJ1: W_110 | EK1: D_111 | EL1: W_111 | EM1: D_112 | EN1: W_112 | EO1: D_113 | EP1: W_113 | EQ1: D_114 | ER1: W_114 | ES1: D_115 | ET1: W_115 | EU1: D_116 | EV1: W_116 | EW1: D_117 | EX1: W_117 | EY1: D_118 | EZ1: W_118 | FA1: D_119 | FB1: W_119 | FC1: D_120 | FD1: W_120 | FE1: D_121 | FF1: W_121 | FG1: D_122 | FH1: W_122 | FI1: D_123 | FJ1: W_123 | FK1: D_124 | FL1: W_124 | FM1: D_125 | FN1: W_125 | FO1: D_126 | FP1: W_126 | FQ1: D_139 | FR1: W_139 | FS1: D_140 | FT1: W_140 | FU1: D_141 | FV1: W_141 | FW1: D_142 | FX1: W_142 | FY1: D_143 | FZ1: W_143 | GA1: D_144 | GB1: W_144 | GC1: D_145 | GD1: W_145 | GE1: D_146 | GF1: W_146 | GG1: D_147 | GH1: W_147 | GI1: D_148 | GJ1: W_148 | GK1: D_149 | GL1: W_149 | GM1: D_150 | GN1: W_150 | GO1: D_151 | GP1: W_151 | GQ1: D_152 | GR1: W_152 | GS1: D_153 | GT1: W_153 | GU1: D_154 | GV1: W_154 | GW1: D_155 | GX1: W_155 | GY1: D_156 | GZ1: W_156 | HA1: D_157 | HB1: W_157 | HC1: D_158 | HD1: W_158 | HE1: D_159 | HF1: W_159 | HG1: D_160 | HH1: W_160 | HI1: D_161 | HJ1: W_161 | HK1: D_162 | HL1: W_162 | HM1: D_163 | HN1: W_163 | HO1: D_164 | HP1: W_164 | HQ1: D_165 | HR1: W_165 | HS1: D_166 | HT1: W_166 | HU1: D_167 | HV1: W_167 | HW1: D_168 | HX1: W_168 | HY1: D_169 | HZ1: W_169 | IA1: D_170 | IB1: W_170 | IC1: D_171 | ID1: W_171 | IE1: D_173 | IF1: W_173 | IG1: D_174 | IH1: W_174
A2: seq16_binder | B2: 16 | C2: binder | D2: =IF(C2="Binder", 1,0) -> 1 | F2: MPSELTPEERSELKNSIAEFHTYQLDPGQCSSLHAQRIHAPPDLVWSIVRRFDKPQTYVPFIKSCSVEQNFEMRVGCTREDILISGLPASTMTVRLDILDDERRVTGASVIGGEHRVRNLKTVTTVHRFEKENKIWTVVLKSYVVDMPEGNSEDDTRMILDTGVKLILQKLATVAEAMARN | G2: =_xlfn.XLOOKUP(A2,rmsf_ca_per_seq_summary_500ns!$A$2:$A$195,rmsf_ca_per_seq_summary_500ns!$C$2:$C$195) -> 0.31071 | H2: =_xlfn.XLOOKUP(A2,rmsf_ca_per_seq_summary_500ns!$A$2:$A$195,rmsf_ca_per_seq_summary_500ns!$D$2:$D$195) -> 0.05224 | I2: =_xlfn.XLOOKUP($A2,gate_latch_rmsd_to_ref_500ns!$A$2:$A$195,gate_latch_rmsd_to_ref_500ns!$I$2:$I$195) -> 2.54 | J2: =_xlfn.XLOOKUP($A2,gate_latch_rmsd_to_ref_500ns!$A$2:$A$195,gate_latch_rmsd_to_ref_500ns!$M$2:$M$195) -> 1.253 | K2: =_xlfn.XLOOKUP($A2,contact_features_all_40_500ns!$A$2:$A$195,contact_features_all_40_500ns!$E$2:$E$195) -> 2.1300236 | L2: =_xlfn.XLOOKUP($A2,contact_features_all_40_500ns!$A$2:$A$195,contact_features_all_40_500ns!$F$2:$F$195) -> 0.88673881 | M2: =_xlfn.XLOOKUP($A2,contact_features_all_40_500ns!$A$2:$A$195,contact_features_all_40_500ns!$H$2:$H$195) -> 2.6687047 | N2: =_xlfn.XLOOKUP($A2,contact_features_all_40_500ns!$A$2:$A$195,contact_features_all_40_500ns!$I$2:$I$195) -> 0.70132552 | O2: =_xlfn.XLOOKUP($A2,contact_features_all_40_500ns!$A$2:$A$195,contact_features_all_40_500ns!$K$2:$K$195) -> 0.76114779 | P2: =_xlfn.XLOOKUP($A2,contact_features_all_40_500ns!$A$2:$A$195,contact_features_all_40_500ns!$L$2:$L$195) -> 0.46233914 | Q2: =_xlfn.XLOOKUP($A2,rmsf_single_residues_per_seq_50!$A$2:$A$195,rmsf_single_residues_per_seq_50!$E$2:$E$195) -> 2.893 | R2: =_xlfn.XLOOKUP($A2,rmsf_single_residues_per_seq_50!$A$2:$A$195,rmsf_single_residues_per_seq_50!$G$2:$G$195) -> 0.546 | S2: =_xlfn.XLOOKUP($A2,rmsf_single_residues_per_seq_50!$A$2:$A$195,rmsf_single_residues_per_seq_50!$H$2:$H$195) -> 0.676 | T2: =_xlfn.XLOOKUP($A2,rmsf_single_residues_per_seq_50!$A$2:$A$195,rmsf_single_residues_per_seq_50!$I$2:$I$195) -> 0.759 | U2: =_xlfn.XLOOKUP($A2,dw_scores_all_sequences_40_500n!$A$2:$A$195,dw_scores_all_sequences_40_500n!C$2:C$195) -> 0 | V2: =_xlfn.XLOOKUP($A2,dw_scores_all_sequences_40_500n!$A$2:$A$195,dw_scores_all_sequences_40_500n!D$2:D$195) -> 0 | W2: =_xlfn.XLOOKUP($A2,dw_scores_all_sequences_40_500n!$A$2:$A$195,dw_scores_all_sequences_40_500n!E$2:E$195) -> 0 | X2: =_xlfn.XLOOKUP($A2,dw_scores_all_sequences_40_500n!$A$2:$A$195,dw_scores_all_sequences_40_500n!F$2:F$195) -> 0 | Y2: =_xlfn.XLOOKUP($A2,dw_scores_all_sequences_40_500n!$A$2:$A$195,dw_scores_all_sequences_40_500n!G$2:G$195) -> 0 | Z2: =_xlfn.XLOOKUP($A2,dw_scores_all_sequences_40_500n!$A$2:$A$195,dw_scores_all_sequences_40_500n!H$2:H$195) -> 0 | AA2: =_xlfn.XLOOKUP($A2,dw_scores_all_sequences_40_500n!$A$2:$A$195,dw_scores_all_sequences_40_500n!I$2:I$195) -> 0 | AB2: =_xlfn.XLOOKUP($A2,dw_scores_all_sequences_40_500n!$A$2:$A$195,dw_scores_all_sequences_40_500n!J$2:J$195) -> 0 | ... IH2: =_xlfn.XLOOKUP($A2,dw_scores_all_sequences_40_500n!$A$2:$A$195,dw_scores_all_sequences_40_500n!HP$2:HP$195) -> 0
A3: seq14_binder | B3: 14 | C3: binder | D3: =IF(C3="Binder", 1,0) -> 1 | F3: MPSELTPEERSELKNSIAEFHTYQLDPGQCSSLHAQRIHAPPDLVWSIVRRFDKPQTYVPFIKSCSVEQNFEMRVGCTREDILISGLPASTMTLRLDILDDERRVTGASVIGGEHRVRNLKTVTTVHRFEKENKIWTVVLKSYVVDMPEGNSEDDTRMIMDTGIKLILQKLATVAEAMARN | G3: =_xlfn.XLOOKUP(A3,rmsf_ca_per_seq_summary_500ns!$A$2:$A$195,rmsf_ca_per_seq_summary_500ns!$C$2:$C$195) -> 0.28114 | H3: =_xlfn.XLOOKUP(A3,rmsf_ca_per_seq_summary_500ns!$A$2:$A$195,rmsf_ca_per_seq_summary_500ns!$D$2:$D$195) -> 0.05419 | I3: =_xlfn.XLOOKUP($A3,gate_latch_rmsd_to_ref_500ns!$A$2:$A$195,gate_latch_rmsd_to_ref_500ns!$I$2:$I$195) -> 1.5227 | J3: =_xlfn.XLOOKUP($A3,gate_latch_rmsd_to_ref_500ns!$A$2:$A$195,gate_latch_rmsd_to_ref_500ns!$M$2:$M$195) -> 1.5219 | K3: =_xlfn.XLOOKUP($A3,contact_features_all_40_500ns!$A$2:$A$195,contact_features_all_40_500ns!$E$2:$E$195) -> 2.5602022 | L3: =_xlfn.XLOOKUP($A3,contact_features_all_40_500ns!$A$2:$A$195,contact_features_all_40_500ns!$F$2:$F$195) -> 0.52617868 | M3: =_xlfn.XLOOKUP($A3,contact_features_all_40_500ns!$A$2:$A$195,contact_features_all_40_500ns!$H$2:$H$195) -> 2.5500937 | N3: =_xlfn.XLOOKUP($A3,contact_features_all_40_500ns!$A$2:$A$195,contact_features_all_40_500ns!$I$2:$I$195) -> 0.84966714 | O3: =_xlfn.XLOOKUP($A3,contact_features_all_40_500ns!$A$2:$A$195,contact_features_all_40_500ns!$K$2:$K$195) -> 0.69299747 | P3: =_xlfn.XLOOKUP($A3,contact_features_all_40_500ns!$A$2:$A$195,contact_features_all_40_500ns!$L$2:$L$195) -> 0.46125045 | Q3: =_xlfn.XLOOKUP($A3,rmsf_single_residues_per_seq_50!$A$2:$A$195,rmsf_single_residues_per_seq_50!$E$2:$E$195) -> 2.463 | R3: =_xlfn.XLOOKUP($A3,rmsf_single_residues_per_seq_50!$A$2:$A$195,rmsf_single_residues_per_seq_50!$G$2:$G$195) -> 0.51 | S3: =_xlfn.XLOOKUP($A3,rmsf_single_residues_per_seq_50!$A$2:$A$195,rmsf_single_residues_per_seq_50!$H$2:$H$195) -> 0.684 | T3: =_xlfn.XLOOKUP($A3,rmsf_single_residues_per_seq_50!$A$2:$A$195,rmsf_single_residues_per_seq_50!$I$2:$I$195) -> 0.62 | U3: =_xlfn.XLOOKUP($A3,dw_scores_all_sequences_40_500n!$A$2:$A$195,dw_scores_all_sequences_40_500n!C$2:C$195) -> 0 | V3: =_xlfn.XLOOKUP($A3,dw_scores_all_sequences_40_500n!$A$2:$A$195,dw_scores_all_sequences_40_500n!D$2:D$195) -> 0 | W3: =_xlfn.XLOOKUP($A3,dw_scores_all_sequences_40_500n!$A$2:$A$195,dw_scores_all_sequences_40_500n!E$2:E$195) -> 0 | X3: =_xlfn.XLOOKUP($A3,dw_scores_all_sequences_40_500n!$A$2:$A$195,dw_scores_all_sequences_40_500n!F$2:F$195) -> 0 | Y3: =_xlfn.XLOOKUP($A3,dw_scores_all_sequences_40_500n!$A$2:$A$195,dw_scores_all_sequences_40_500n!G$2:G$195) -> 0 | Z3: =_xlfn.XLOOKUP($A3,dw_scores_all_sequences_40_500n!$A$2:$A$195,dw_scores_all_sequences_40_500n!H$2:H$195) -> 0 | AA3: =_xlfn.XLOOKUP($A3,dw_scores_all_sequences_40_500n!$A$2:$A$195,dw_scores_all_sequences_40_500n!I$2:I$195) -> 0 | AB3: =_xlfn.XLOOKUP($A3,dw_scores_all_sequences_40_500n!$A$2:$A$195,dw_scores_all_sequences_40_500n!J$2:J$195) -> 0 | ... IH3: =_xlfn.XLOOKUP($A3,dw_scores_all_sequences_40_500n!$A$2:$A$195,dw_scores_all_sequences_40_500n!HP$2:HP$195) -> 0
A4: seq10_binder | B4: 10 | C4: binder | D4: =IF(C4="Binder", 1,0) -> 1 | F4: MPSELTPEERSELKNSIAEFHTYQLDPGQCSSLHAQRIHAPPDLVWSIVRRFDKPQTYVPFIKSCSVEQNFEMRVGCTREDILISGLPASTMTVRLDILDDERRVTGASVIGGEHRVRNLKTVTTVHRFEKENKIWTVVLKSYVVDMPEGNSEDDTRMIVDTGVKLLLQKLATVAEAMARN | G4: =_xlfn.XLOOKUP(A4,rmsf_ca_per_seq_summary_500ns!$A$2:$A$195,rmsf_ca_per_seq_summary_500ns!$C$2:$C$195) -> 1.0638 | H4: =_xlfn.XLOOKUP(A4,rmsf_ca_per_seq_summary_500ns!$A$2:$A$195,rmsf_ca_per_seq_summary_500ns!$D$2:$D$195) -> 0.47754 | I4: =_xlfn.XLOOKUP($A4,gate_latch_rmsd_to_ref_500ns!$A$2:$A$195,gate_latch_rmsd_to_ref_500ns!$I$2:$I$195) -> 1.4443 | J4: =_xlfn.XLOOKUP($A4,gate_latch_rmsd_to_ref_500ns!$A$2:$A$195,gate_latch_rmsd_to_ref_500ns!$M$2:$M$195) -> 3.0262 | K4: =_xlfn.XLOOKUP($A4,contact_features_all_40_500ns!$A$2:$A$195,contact_features_all_40_500ns!$E$2:$E$195) -> 2.2310263 | L4: =_xlfn.XLOOKUP($A4,contact_features_all_40_500ns!$A$2:$A$195,contact_features_all_40_500ns!$F$2:$F$195) -> 0.65626958 | M4: =_xlfn.XLOOKUP($A4,contact_features_all_40_500ns!$A$2:$A$195,contact_features_all_40_500ns!$H$2:$H$195) -> 2.1719247 | N4: =_xlfn.XLOOKUP($A4,contact_features_all_40_500ns!$A$2:$A$195,contact_features_all_40_500ns!$I$2:$I$195) -> 0.5315827 | O4: =_xlfn.XLOOKUP($A4,contact_features_all_40_500ns!$A$2:$A$195,contact_features_all_40_500ns!$K$2:$K$195) -> 0.62566235 | P4: =_xlfn.XLOOKUP($A4,contact_features_all_40_500ns!$A$2:$A$195,contact_features_all_40_500ns!$L$2:$L$195) -> 0.54405953 | Q4: =_xlfn.XLOOKUP($A4,rmsf_single_residues_per_seq_50!$A$2:$A$195,rmsf_single_residues_per_seq_50!$E$2:$E$195) -> 1.674 | R4: =_xlfn.XLOOKUP($A4,rmsf_single_residues_per_seq_50!$A$2:$A$195,rmsf_single_residues_per_seq_50!$G$2:$G$195) -> 0.805 | S4: =_xlfn.XLOOKUP($A4,rmsf_single_residues_per_seq_50!$A$2:$A$195,rmsf_single_residues_per_seq_50!$H$2:$H$195) -> 0.871 | T4: =_xlfn.XLOOKUP($A4,rmsf_single_residues_per_seq_50!$A$2:$A$195,rmsf_single_residues_per_seq_50!$I$2:$I$195) -> 1.005 | U4: =_xlfn.XLOOKUP($A4,dw_scores_all_sequences_40_500n!$A$2:$A$195,dw_scores_all_sequences_40_500n!C$2:C$195) -> 0 | V4: =_xlfn.XLOOKUP($A4,dw_scores_all_sequences_40_500n!$A$2:$A$195,dw_scores_all_sequences_40_500n!D$2:D$195) -> 0 | W4: =_xlfn.XLOOKUP($A4,dw_scores_all_sequences_40_500n!$A$2:$A$195,dw_scores_all_sequences_40_500n!E$2:E$195) -> 0 | X4: =_xlfn.XLOOKUP($A4,dw_scores_all_sequences_40_500n!$A$2:$A$195,dw_scores_all_sequences_40_500n!F$2:F$195) -> 0 | Y4: =_xlfn.XLOOKUP($A4,dw_scores_all_sequences_40_500n!$A$2:$A$195,dw_scores_all_sequences_40_500n!G$2:G$195) -> 0 | Z4: =_xlfn.XLOOKUP($A4,dw_scores_all_sequences_40_500n!$A$2:$A$195,dw_scores_all_sequences_40_500n!H$2:H$195) -> 0 | AA4: =_xlfn.XLOOKUP($A4,dw_scores_all_sequences_40_500n!$A$2:$A$195,dw_scores_all_sequences_40_500n!I$2:I$195) -> 0 | AB4: =_xlfn.XLOOKUP($A4,dw_scores_all_sequences_40_500n!$A$2:$A$195,dw_scores_all_sequences_40_500n!J$2:J$195) -> 0 | ... IH4: =_xlfn.XLOOKUP($A4,dw_scores_all_sequences_40_500n!$A$2:$A$195,dw_scores_all_sequences_40_500n!HP$2:HP$195) -> 0
A5: seq17_binder | B5: 17 | C5: binder | D5: =IF(C5="Binder", 1,0) -> 1 | F5: MPSELTPEERSELKNSIAEFHTYQLDPGQCSSLHAQRIHAPPDLVWSIVRRFDKPQTYAPFIKSCSVEQNFEMRVGCTREDILISGLPASTMTVRLDILDDERRVTGVSIIGGEHRLRNYKSVTTVHRFEKENKIWTVVLKSYVVDMPEGNSEDDTRMILDTGVKLILQKLATVAEAMARN | G5: =_xlfn.XLOOKUP(A5,rmsf_ca_per_seq_summary_500ns!$A$2:$A$195,rmsf_ca_per_seq_summary_500ns!$C$2:$C$195) -> 0.29129 | H5: =_xlfn.XLOOKUP(A5,rmsf_ca_per_seq_summary_500ns!$A$2:$A$195,rmsf_ca_per_seq_summary_500ns!$D$2:$D$195) -> 0.04837 | I5: =_xlfn.XLOOKUP($A5,gate_latch_rmsd_to_ref_500ns!$A$2:$A$195,gate_latch_rmsd_to_ref_500ns!$I$2:$I$195) -> 2.1259 | J5: =_xlfn.XLOOKUP($A5,gate_latch_rmsd_to_ref_500ns!$A$2:$A$195,gate_latch_rmsd_to_ref_500ns!$M$2:$M$195) -> 2.6499 | K5: =_xlfn.XLOOKUP($A5,contact_features_all_40_500ns!$A$2:$A$195,contact_features_all_40_500ns!$E$2:$E$195) -> 2.4638461 | L5: =_xlfn.XLOOKUP($A5,contact_features_all_40_500ns!$A$2:$A$195,contact_features_all_40_500ns!$F$2:$F$195) -> 0.54717277 | M5: =_xlfn.XLOOKUP($A5,contact_features_all_40_500ns!$A$2:$A$195,contact_features_all_40_500ns!$H$2:$H$195) -> 2.9130187 | N5: =_xlfn.XLOOKUP($A5,contact_features_all_40_500ns!$A$2:$A$195,contact_features_all_40_500ns!$I$2:$I$195) -> 0.45523422 | O5: =_xlfn.XLOOKUP($A5,contact_features_all_40_500ns!$A$2:$A$195,contact_features_all_40_500ns!$K$2:$K$195) -> 0.20803783 | P5: =_xlfn.XLOOKUP($A5,contact_features_all_40_500ns!$A$2:$A$195,contact_features_all_40_500ns!$L$2:$L$195) -> 0.40590404 | Q5: =_xlfn.XLOOKUP($A5,rmsf_single_residues_per_seq_50!$A$2:$A$195,rmsf_single_residues_per_seq_50!$E$2:$E$195) -> 1.387 | R5: =_xlfn.XLOOKUP($A5,rmsf_single_residues_per_seq_50!$A$2:$A$195,rmsf_single_residues_per_seq_50!$G$2:$G$195) -> 0.573 | S5: =_xlfn.XLOOKUP($A5,rmsf_single_residues_per_seq_50!$A$2:$A$195,rmsf_single_residues_per_seq_50!$H$2:$H$195) -> 0.682 | T5: =_xlfn.XLOOKUP($A5,rmsf_single_residues_per_seq_50!$A$2:$A$195,rmsf_single_residues_per_seq_50!$I$2:$I$195) -> 0.598 | U5: =_xlfn.XLOOKUP($A5,dw_scores_all_sequences_40_500n!$A$2:$A$195,dw_scores_all_sequences_40_500n!C$2:C$195) -> 0 | V5: =_xlfn.XLOOKUP($A5,dw_scores_all_sequences_40_500n!$A$2:$A$195,dw_scores_all_sequences_40_500n!D$2:D$195) -> 0 | W5: =_xlfn.XLOOKUP($A5,dw_scores_all_sequences_40_500n!$A$2:$A$195,dw_scores_all_sequences_40_500n!E$2:E$195) -> 0 | X5: =_xlfn.XLOOKUP($A5,dw_scores_all_sequences_40_500n!$A$2:$A$195,dw_scores_all_sequences_40_500n!F$2:F$195) -> 0 | Y5: =_xlfn.XLOOKUP($A5,dw_scores_all_sequences_40_500n!$A$2:$A$195,dw_scores_all_sequences_40_500n!G$2:G$195) -> 0 | Z5: =_xlfn.XLOOKUP($A5,dw_scores_all_sequences_40_500n!$A$2:$A$195,dw_scores_all_sequences_40_500n!H$2:H$195) -> 0 | AA5: =_xlfn.XLOOKUP($A5,dw_scores_all_sequences_40_500n!$A$2:$A$195,dw_scores_all_sequences_40_500n!I$2:I$195) -> 0 | AB5: =_xlfn.XLOOKUP($A5,dw_scores_all_sequences_40_500n!$A$2:$A$195,dw_scores_all_sequences_40_500n!J$2:J$195) -> 0 | ... IH5: =_xlfn.XLOOKUP($A5,dw_scores_all_sequences_40_500n!$A$2:$A$195,dw_scores_all_sequences_40_500n!HP$2:HP$195) -> 0
A6: seq39_binder | B6: 39 | C6: binder | D6: =IF(C6="Binder", 1,0) -> 1 | F6: MPSELTPEERSELKNSIAEFHTYQLDPGQCSSLHAQRIHAPPDLVWSIVRRFDKPQTYVPFIKSCSVEQNFEMRVGCTREDILISGLPASTMTVRLDILDDERRVTGASVIGGEHRLRNYKSVTTVHRFEKENKIWTVVLKSYVVDMPEGNSEDDTRMIVDTGVKLLLQKLATVAEAMARN | G6: =_xlfn.XLOOKUP(A6,rmsf_ca_per_seq_summary_500ns!$A$2:$A$195,rmsf_ca_per_seq_summary_500ns!$C$2:$C$195) -> 0.366 | H6: =_xlfn.XLOOKUP(A6,rmsf_ca_per_seq_summary_500ns!$A$2:$A$195,rmsf_ca_per_seq_summary_500ns!$D$2:$D$195) -> 0.05587 | I6: =_xlfn.XLOOKUP($A6,gate_latch_rmsd_to_ref_500ns!$A$2:$A$195,gate_latch_rmsd_to_ref_500ns!$I$2:$I$195) -> 1.328 | J6: =_xlfn.XLOOKUP($A6,gate_latch_rmsd_to_ref_500ns!$A$2:$A$195,gate_latch_rmsd_to_ref_500ns!$M$2:$M$195) -> 2.9569 | K6: =_xlfn.XLOOKUP($A6,contact_features_all_40_500ns!$A$2:$A$195,contact_features_all_40_500ns!$E$2:$E$195) -> 2.315073 | L6: =_xlfn.XLOOKUP($A6,contact_features_all_40_500ns!$A$2:$A$195,contact_features_all_40_500ns!$F$2:$F$195) -> 1.1589021 | M6: =_xlfn.XLOOKUP($A6,contact_features_all_40_500ns!$A$2:$A$195,contact_features_all_40_500ns!$H$2:$H$195) -> 1.9024211 | N6: =_xlfn.XLOOKUP($A6,contact_features_all_40_500ns!$A$2:$A$195,contact_features_all_40_500ns!$I$2:$I$195) -> 0.50530713 | O6: =_xlfn.XLOOKUP($A6,contact_features_all_40_500ns!$A$2:$A$195,contact_features_all_40_500ns!$K$2:$K$195) -> 0.8500856 | P6: =_xlfn.XLOOKUP($A6,contact_features_all_40_500ns!$A$2:$A$195,contact_features_all_40_500ns!$L$2:$L$195) -> 0.36533891 | Q6: =_xlfn.XLOOKUP($A6,rmsf_single_residues_per_seq_50!$A$2:$A$195,rmsf_single_residues_per_seq_50!$E$2:$E$195) -> 2.16 | R6: =_xlfn.XLOOKUP($A6,rmsf_single_residues_per_seq_50!$A$2:$A$195,rmsf_single_residues_per_seq_50!$G$2:$G$195) -> 0.663 | S6: =_xlfn.XLOOKUP($A6,rmsf_single_residues_per_seq_50!$A$2:$A$195,rmsf_single_residues_per_seq_50!$H$2:$H$195) -> 0.671 | T6: =_xlfn.XLOOKUP($A6,rmsf_single_residues_per_seq_50!$A$2:$A$195,rmsf_single_residues_per_seq_50!$I$2:$I$195) -> 1.319 | U6: =_xlfn.XLOOKUP($A6,dw_scores_all_sequences_40_500n!$A$2:$A$195,dw_scores_all_sequences_40_500n!C$2:C$195) -> 0 | V6: =_xlfn.XLOOKUP($A6,dw_scores_all_sequences_40_500n!$A$2:$A$195,dw_scores_all_sequences_40_500n!D$2:D$195) -> 0 | W6: =_xlfn.XLOOKUP($A6,dw_scores_all_sequences_40_500n!$A$2:$A$195,dw_scores_all_sequences_40_500n!E$2:E$195) -> 0 | X6: =_xlfn.XLOOKUP($A6,dw_scores_all_sequences_40_500n!$A$2:$A$195,dw_scores_all_sequences_40_500n!F$2:F$195) -> 0 | Y6: =_xlfn.XLOOKUP($A6,dw_scores_all_sequences_40_500n!$A$2:$A$195,dw_scores_all_sequences_40_500n!G$2:G$195) -> 0 | Z6: =_xlfn.XLOOKUP($A6,dw_scores_all_sequences_40_500n!$A$2:$A$195,dw_scores_all_sequences_40_500n!H$2:H$195) -> 0 | AA6: =_xlfn.XLOOKUP($A6,dw_scores_all_sequences_40_500n!$A$2:$A$195,dw_scores_all_sequences_40_500n!I$2:I$195) -> 0 | AB6: =_xlfn.XLOOKUP($A6,dw_scores_all_sequences_40_500n!$A$2:$A$195,dw_scores_all_sequences_40_500n!J$2:J$195) -> 0 | ... IH6: =_xlfn.XLOOKUP($A6,dw_scores_all_sequences_40_500n!$A$2:$A$195,dw_scores_all_sequences_40_500n!HP$2:HP$195) -> 0
A7: seq42_binder | B7: 42 | C7: binder | D7: =IF(C7="Binder", 1,0) -> 1 | F7: MPSELTPEERSELKNSIAEFHTYQLDPGQCSSLHAQRIHAPPDLVWSIVRRFDKPQTYLPFIKSCSVEQNFEMRVGCTRELIVISGLPASTATVRLDILDDERRVTGGSVIGGEHRLRNLKWVTTVHRFEKENKIWTVVLQSYVVDMPEGNSEDDTRMYVDTFIKLVLQKLATVAEAMARN | G7: =_xlfn.XLOOKUP(A7,rmsf_ca_per_seq_summary_500ns!$A$2:$A$195,rmsf_ca_per_seq_summary_500ns!$C$2:$C$195) -> 0.305 | H7: =_xlfn.XLOOKUP(A7,rmsf_ca_per_seq_summary_500ns!$A$2:$A$195,rmsf_ca_per_seq_summary_500ns!$D$2:$D$195) -> 0.05492 | I7: =_xlfn.XLOOKUP($A7,gate_latch_rmsd_to_ref_500ns!$A$2:$A$195,gate_latch_rmsd_to_ref_500ns!$I$2:$I$195) -> 2.7893 | J7: =_xlfn.XLOOKUP($A7,gate_latch_rmsd_to_ref_500ns!$A$2:$A$195,gate_latch_rmsd_to_ref_500ns!$M$2:$M$195) -> 4.1589 | K7: =_xlfn.XLOOKUP($A7,contact_features_all_40_500ns!$A$2:$A$195,contact_features_all_40_500ns!$E$2:$E$195) -> 2.4099617 | L7: =_xlfn.XLOOKUP($A7,contact_features_all_40_500ns!$A$2:$A$195,contact_features_all_40_500ns!$F$2:$F$195) -> 0.90483438 | M7: =_xlfn.XLOOKUP($A7,contact_features_all_40_500ns!$A$2:$A$195,contact_features_all_40_500ns!$H$2:$H$195) -> 0.92671395 | N7: =_xlfn.XLOOKUP($A7,contact_features_all_40_500ns!$A$2:$A$195,contact_features_all_40_500ns!$I$2:$I$195) -> 0.52794384 | O7: =_xlfn.XLOOKUP($A7,contact_features_all_40_500ns!$A$2:$A$195,contact_features_all_40_500ns!$K$2:$K$195) -> 0.0081519524 | P7: =_xlfn.XLOOKUP($A7,contact_features_all_40_500ns!$A$2:$A$195,contact_features_all_40_500ns!$L$2:$L$195) -> 0.089919398 | Q7: =_xlfn.XLOOKUP($A7,rmsf_single_residues_per_seq_50!$A$2:$A$195,rmsf_single_residues_per_seq_50!$E$2:$E$195) -> 2.926 | R7: =_xlfn.XLOOKUP($A7,rmsf_single_residues_per_seq_50!$A$2:$A$195,rmsf_single_residues_per_seq_50!$G$2:$G$195) -> 1.628 | S7: =_xlfn.XLOOKUP($A7,rmsf_single_residues_per_seq_50!$A$2:$A$195,rmsf_single_residues_per_seq_50!$H$2:$H$195) -> 0.947 | T7: =_xlfn.XLOOKUP($A7,rmsf_single_residues_per_seq_50!$A$2:$A$195,rmsf_single_residues_per_seq_50!$I$2:$I$195) -> 1.015 | U7: =_xlfn.XLOOKUP($A7,dw_scores_all_sequences_40_500n!$A$2:$A$195,dw_scores_all_sequences_40_500n!C$2:C$195) -> 0 | V7: =_xlfn.XLOOKUP($A7,dw_scores_all_sequences_40_500n!$A$2:$A$195,dw_scores_all_sequences_40_500n!D$2:D$195) -> 0 | W7: =_xlfn.XLOOKUP($A7,dw_scores_all_sequences_40_500n!$A$2:$A$195,dw_scores_all_sequences_40_500n!E$2:E$195) -> 0 | X7: =_xlfn.XLOOKUP($A7,dw_scores_all_sequences_40_500n!$A$2:$A$195,dw_scores_all_sequences_40_500n!F$2:F$195) -> 0 | Y7: =_xlfn.XLOOKUP($A7,dw_scores_all_sequences_40_500n!$A$2:$A$195,dw_scores_all_sequences_40_500n!G$2:G$195) -> 0 | Z7: =_xlfn.XLOOKUP($A7,dw_scores_all_sequences_40_500n!$A$2:$A$195,dw_scores_all_sequences_40_500n!H$2:H$195) -> 0 | AA7: =_xlfn.XLOOKUP($A7,dw_scores_all_sequences_40_500n!$A$2:$A$195,dw_scores_all_sequences_40_500n!I$2:I$195) -> 0 | AB7: =_xlfn.XLOOKUP($A7,dw_scores_all_sequences_40_500n!$A$2:$A$195,dw_scores_all_sequences_40_500n!J$2:J$195) -> 0 | ... IH7: =_xlfn.XLOOKUP($A7,dw_scores_all_sequences_40_500n!$A$2:$A$195,dw_scores_all_sequences_40_500n!HP$2:HP$195) -> 0
A8: pair_3069_binder | B8: 3069 | C8: binder | D8: =IF(C8="Binder", 1,0) -> 1 | E8: 0.7232 | F8: MASELTPEERSELKNSIAEFHTYQLDPGSCSSLHAQRIHAPPELVWSIVRRFDKPQTYAHFIKSCSVEQNFEMRVGCTRDDILISGLPANTMTVRLDILDDERRVTGVSIIGGEHRLTNYKSVTTVHRFEKENRIWTVVLKSYVVDMPEGNSEDDTRMILDTGVKLILQKLATVAEAMARN | G8: =_xlfn.XLOOKUP(A8,rmsf_ca_per_seq_summary_500ns!$A$2:$A$195,rmsf_ca_per_seq_summary_500ns!$C$2:$C$195) -> 0.37043 | H8: =_xlfn.XLOOKUP(A8,rmsf_ca_per_seq_summary_500ns!$A$2:$A$195,rmsf_ca_per_seq_summary_500ns!$D$2:$D$195) -> 0.08798 | I8: =_xlfn.XLOOKUP($A8,gate_latch_rmsd_to_ref_500ns!$A$2:$A$195,gate_latch_rmsd_to_ref_500ns!$I$2:$I$195) -> 2.7978 | J8: =_xlfn.XLOOKUP($A8,gate_latch_rmsd_to_ref_500ns!$A$2:$A$195,gate_latch_rmsd_to_ref_500ns!$M$2:$M$195) -> 4.9449 | K8: =_xlfn.XLOOKUP($A8,contact_features_all_40_500ns!$A$2:$A$195,contact_features_all_40_500ns!$E$2:$E$195) -> 1.7655498 | L8: =_xlfn.XLOOKUP($A8,contact_features_all_40_500ns!$A$2:$A$195,contact_features_all_40_500ns!$F$2:$F$195) -> 0.65080929 | M8: =_xlfn.XLOOKUP($A8,contact_features_all_40_500ns!$A$2:$A$195,contact_features_all_40_500ns!$H$2:$H$195) -> 2.5426755 | N8: =_xlfn.XLOOKUP($A8,contact_features_all_40_500ns!$A$2:$A$195,contact_features_all_40_500ns!$I$2:$I$195) -> 0.92748444 | O8: =_xlfn.XLOOKUP($A8,contact_features_all_40_500ns!$A$2:$A$195,contact_features_all_40_500ns!$K$2:$K$195) -> 0.19197848 | P8: =_xlfn.XLOOKUP($A8,contact_features_all_40_500ns!$A$2:$A$195,contact_features_all_40_500ns!$L$2:$L$195) -> 0.39488978 | Q8: =_xlfn.XLOOKUP($A8,rmsf_single_residues_per_seq_50!$A$2:$A$195,rmsf_single_residues_per_seq_50!$E$2:$E$195) -> 1.196 | R8: =_xlfn.XLOOKUP($A8,rmsf_single_residues_per_seq_50!$A$2:$A$195,rmsf_single_residues_per_seq_50!$G$2:$G$195) -> 0.789 | S8: =_xlfn.XLOOKUP($A8,rmsf_single_residues_per_seq_50!$A$2:$A$195,rmsf_single_residues_per_seq_50!$H$2:$H$195) -> 0.783 | T8: =_xlfn.XLOOKUP($A8,rmsf_single_residues_per_seq_50!$A$2:$A$195,rmsf_single_residues_per_seq_50!$I$2:$I$195) -> 1.13 | U8: =_xlfn.XLOOKUP($A8,dw_scores_all_sequences_40_500n!$A$2:$A$195,dw_scores_all_sequences_40_500n!C$2:C$195) -> 0 | V8: =_xlfn.XLOOKUP($A8,dw_scores_all_sequences_40_500n!$A$2:$A$195,dw_scores_all_sequences_40_500n!D$2:D$195) -> 0 | W8: =_xlfn.XLOOKUP($A8,dw_scores_all_sequences_40_500n!$A$2:$A$195,dw_scores_all_sequences_40_500n!E$2:E$195) -> 0 | X8: =_xlfn.XLOOKUP($A8,dw_scores_all_sequences_40_500n!$A$2:$A$195,dw_scores_all_sequences_40_500n!F$2:F$195) -> 0 | Y8: =_xlfn.XLOOKUP($A8,dw_scores_all_sequences_40_500n!$A$2:$A$195,dw_scores_all_sequences_40_500n!G$2:G$195) -> 0 | Z8: =_xlfn.XLOOKUP($A8,dw_scores_all_sequences_40_500n!$A$2:$A$195,dw_scores_all_sequences_40_500n!H$2:H$195) -> 0 | AA8: =_xlfn.XLOOKUP($A8,dw_scores_all_sequences_40_500n!$A$2:$A$195,dw_scores_all_sequences_40_500n!I$2:I$195) -> 0 | AB8: =_xlfn.XLOOKUP($A8,dw_scores_all_sequences_40_500n!$A$2:$A$195,dw_scores_all_sequences_40_500n!J$2:J$195) -> 0 | ... IH8: =_xlfn.XLOOKUP($A8,dw_scores_all_sequences_40_500n!$A$2:$A$195,dw_scores_all_sequences_40_500n!HP$2:HP$195) -> 0
A9: pair_3070_binder | B9: 3070 | C9: binder | D9: =IF(C9="Binder", 1,0) -> 1 | E9: 0.6667 | F9: MASELTPEERSELKNSIAEFHTYQLDPGSCSSLHAQRIHAPPELVWSIVRRFDKPQTYAHFIKSCSVEQNFEMRVGCTRDDILISGLPANTMTVRLDILDDERRVTGASVIGGEHRLTNYKSVTTVHRFEKENRIWTVVLKSYVVDMPEGNSEDDTRMIVDTGVKLLLQKLATVAEAMARN | G9: =_xlfn.XLOOKUP(A9,rmsf_ca_per_seq_summary_500ns!$A$2:$A$195,rmsf_ca_per_seq_summary_500ns!$C$2:$C$195) -> 0.31829 | H9: =_xlfn.XLOOKUP(A9,rmsf_ca_per_seq_summary_500ns!$A$2:$A$195,rmsf_ca_per_seq_summary_500ns!$D$2:$D$195) -> 0.04939 | I9: =_xlfn.XLOOKUP($A9,gate_latch_rmsd_to_ref_500ns!$A$2:$A$195,gate_latch_rmsd_to_ref_500ns!$I$2:$I$195) -> 1.7093 | J9: =_xlfn.XLOOKUP($A9,gate_latch_rmsd_to_ref_500ns!$A$2:$A$195,gate_latch_rmsd_to_ref_500ns!$M$2:$M$195) -> 1.6324 | K9: =_xlfn.XLOOKUP($A9,contact_features_all_40_500ns!$A$2:$A$195,contact_features_all_40_500ns!$E$2:$E$195) -> 2.494905 | L9: =_xlfn.XLOOKUP($A9,contact_features_all_40_500ns!$A$2:$A$195,contact_features_all_40_500ns!$F$2:$F$195) -> 1.3500551 | M9: =_xlfn.XLOOKUP($A9,contact_features_all_40_500ns!$A$2:$A$195,contact_features_all_40_500ns!$H$2:$H$195) -> 1.8649221 | N9: =_xlfn.XLOOKUP($A9,contact_features_all_40_500ns!$A$2:$A$195,contact_features_all_40_500ns!$I$2:$I$195) -> 0.63518066 | O9: =_xlfn.XLOOKUP($A9,contact_features_all_40_500ns!$A$2:$A$195,contact_features_all_40_500ns!$K$2:$K$195) -> 0.43278715 | P9: =_xlfn.XLOOKUP($A9,contact_features_all_40_500ns!$A$2:$A$195,contact_features_all_40_500ns!$L$2:$L$195) -> 0.49546184 | Q9: =_xlfn.XLOOKUP($A9,rmsf_single_residues_per_seq_50!$A$2:$A$195,rmsf_single_residues_per_seq_50!$E$2:$E$195) -> 1.538 | R9: =_xlfn.XLOOKUP($A9,rmsf_single_residues_per_seq_50!$A$2:$A$195,rmsf_single_residues_per_seq_50!$G$2:$G$195) -> 0.718 | S9: =_xlfn.XLOOKUP($A9,rmsf_single_residues_per_seq_50!$A$2:$A$195,rmsf_single_residues_per_seq_50!$H$2:$H$195) -> 0.665 | T9: =_xlfn.XLOOKUP($A9,rmsf_single_residues_per_seq_50!$A$2:$A$195,rmsf_single_residues_per_seq_50!$I$2:$I$195) -> 0.637 | U9: =_xlfn.XLOOKUP($A9,dw_scores_all_sequences_40_500n!$A$2:$A$195,dw_scores_all_sequences_40_500n!C$2:C$195) -> 0 | V9: =_xlfn.XLOOKUP($A9,dw_scores_all_sequences_40_500n!$A$2:$A$195,dw_scores_all_sequences_40_500n!D$2:D$195) -> 0 | W9: =_xlfn.XLOOKUP($A9,dw_scores_all_sequences_40_500n!$A$2:$A$195,dw_scores_all_sequences_40_500n!E$2:E$195) -> 0 | X9: =_xlfn.XLOOKUP($A9,dw_scores_all_sequences_40_500n!$A$2:$A$195,dw_scores_all_sequences_40_500n!F$2:F$195) -> 0 | Y9: =_xlfn.XLOOKUP($A9,dw_scores_all_sequences_40_500n!$A$2:$A$195,dw_scores_all_sequences_40_500n!G$2:G$195) -> 0 | Z9: =_xlfn.XLOOKUP($A9,dw_scores_all_sequences_40_500n!$A$2:$A$195,dw_scores_all_sequences_40_500n!H$2:H$195) -> 0 | AA9: =_xlfn.XLOOKUP($A9,dw_scores_all_sequences_40_500n!$A$2:$A$195,dw_scores_all_sequences_40_500n!I$2:I$195) -> 0 | AB9: =_xlfn.XLOOKUP($A9,dw_scores_all_sequences_40_500n!$A$2:$A$195,dw_scores_all_sequences_40_500n!J$2:J$195) -> 0 | ... IH9: =_xlfn.XLOOKUP($A9,dw_scores_all_sequences_40_500n!$A$2:$A$195,dw_scores_all_sequences_40_500n!HP$2:HP$195) -> 0
A10: pair_3074_binder | B10: 3074 | C10: binder | D10: =IF(C10="Binder", 1,0) -> 1 | E10: 0.7 | F10: MASELTPEERSELKNSIAEFHTYQLDPGSCSSLHAQRIHAPPELVWSIVRRFDKPQTYAHFIKSCSVEQNFEMRVGCTRDDILISGLPANTMTVRLDILDDERRVTGVSIIGGEHRLTNYKSVTTVHRFEKENRIWTVVLKSYVVDMPEGNSEDDTRMHVDTLTKLALQKLATVAEAMARN | G10: =_xlfn.XLOOKUP(A10,rmsf_ca_per_seq_summary_500ns!$A$2:$A$195,rmsf_ca_per_seq_summary_500ns!$C$2:$C$195) -> 0.33186 | H10: =_xlfn.XLOOKUP(A10,rmsf_ca_per_seq_summary_500ns!$A$2:$A$195,rmsf_ca_per_seq_summary_500ns!$D$2:$D$195) -> 0.06673 | I10: =_xlfn.XLOOKUP($A10,gate_latch_rmsd_to_ref_500ns!$A$2:$A$195,gate_latch_rmsd_to_ref_500ns!$I$2:$I$195) -> 1.7977 | J10: =_xlfn.XLOOKUP($A10,gate_latch_rmsd_to_ref_500ns!$A$2:$A$195,gate_latch_rmsd_to_ref_500ns!$M$2:$M$195) -> 2.0618 | K10: =_xlfn.XLOOKUP($A10,contact_features_all_40_500ns!$A$2:$A$195,contact_features_all_40_500ns!$E$2:$E$195) -> 2.7791636 | L10: =_xlfn.XLOOKUP($A10,contact_features_all_40_500ns!$A$2:$A$195,contact_features_all_40_500ns!$F$2:$F$195) -> 0.92934349 | M10: =_xlfn.XLOOKUP($A10,contact_features_all_40_500ns!$A$2:$A$195,contact_features_all_40_500ns!$H$2:$H$195) -> 3.2813239 | N10: =_xlfn.XLOOKUP($A10,contact_features_all_40_500ns!$A$2:$A$195,contact_features_all_40_500ns!$I$2:$I$195) -> 0.73117534 | O10: =_xlfn.XLOOKUP($A10,contact_features_all_40_500ns!$A$2:$A$195,contact_features_all_40_500ns!$K$2:$K$195) -> 0.31931198 | P10: =_xlfn.XLOOKUP($A10,contact_features_all_40_500ns!$A$2:$A$195,contact_features_all_40_500ns!$L$2:$L$195) -> 0.46673435 | Q10: =_xlfn.XLOOKUP($A10,rmsf_single_residues_per_seq_50!$A$2:$A$195,rmsf_single_residues_per_seq_50!$E$2:$E$195) -> 2.508 | R10: =_xlfn.XLOOKUP($A10,rmsf_single_residues_per_seq_50!$A$2:$A$195,rmsf_single_residues_per_seq_50!$G$2:$G$195) -> 0.816 | S10: =_xlfn.XLOOKUP($A10,rmsf_single_residues_per_seq_50!$A$2:$A$195,rmsf_single_residues_per_seq_50!$H$2:$H$195) -> 0.766 | T10: =_xlfn.XLOOKUP($A10,rmsf_single_residues_per_seq_50!$A$2:$A$195,rmsf_single_residues_per_seq_50!$I$2:$I$195) -> 1.134 | U10: =_xlfn.XLOOKUP($A10,dw_scores_all_sequences_40_500n!$A$2:$A$195,dw_scores_all_sequences_40_500n!C$2:C$195) -> 0 | V10: =_xlfn.XLOOKUP($A10,dw_scores_all_sequences_40_500n!$A$2:$A$195,dw_scores_all_sequences_40_500n!D$2:D$195) -> 0 | W10: =_xlfn.XLOOKUP($A10,dw_scores_all_sequences_40_500n!$A$2:$A$195,dw_scores_all_sequences_40_500n!E$2:E$195) -> 0 | X10: =_xlfn.XLOOKUP($A10,dw_scores_all_sequences_40_500n!$A$2:$A$195,dw_scores_all_sequences_40_500n!F$2:F$195) -> 0 | Y10: =_xlfn.XLOOKUP($A10,dw_scores_all_sequences_40_500n!$A$2:$A$195,dw_scores_all_sequences_40_500n!G$2:G$195) -> 0 | Z10: =_xlfn.XLOOKUP($A10,dw_scores_all_sequences_40_500n!$A$2:$A$195,dw_scores_all_sequences_40_500n!H$2:H$195) -> 0 | AA10: =_xlfn.XLOOKUP($A10,dw_scores_all_sequences_40_500n!$A$2:$A$195,dw_scores_all_sequences_40_500n!I$2:I$195) -> 0 | AB10: =_xlfn.XLOOKUP($A10,dw_scores_all_sequences_40_500n!$A$2:$A$195,dw_scores_all_sequences_40_500n!J$2:J$195) -> 0 | ... IH10: =_xlfn.XLOOKUP($A10,dw_scores_all_sequences_40_500n!$A$2:$A$195,dw_scores_all_sequences_40_500n!HP$2:HP$195) -> 0
A11: pair_3092_binder | B11: 3092 | C11: binder | D11: =IF(C11="Binder", 1,0) -> 1 | E11: 0.5769 | F11: MASELTPEERSELKNSIAEFHTYQLDPGSCSSLHAQRIHAPPELVWSIVRRFDKPQTYVHFIKSCSVEQNFEMRVGCTRDDILISGLPANTMTVRLDILDDERRVTGASVIGGEHRLTNYKSVTTVHRFEKENRIWTVVLKSYVVDMPEGNSEDDTRMIVDTGVKLLLQKLATVAEAMARN | G11: =_xlfn.XLOOKUP(A11,rmsf_ca_per_seq_summary_500ns!$A$2:$A$195,rmsf_ca_per_seq_summary_500ns!$C$2:$C$195) -> 0.33371 | H11: =_xlfn.XLOOKUP(A11,rmsf_ca_per_seq_summary_500ns!$A$2:$A$195,rmsf_ca_per_seq_summary_500ns!$D$2:$D$195) -> 0.0508 | I11: =_xlfn.XLOOKUP($A11,gate_latch_rmsd_to_ref_500ns!$A$2:$A$195,gate_latch_rmsd_to_ref_500ns!$I$2:$I$195) -> 1.3232 | J11: =_xlfn.XLOOKUP($A11,gate_latch_rmsd_to_ref_500ns!$A$2:$A$195,gate_latch_rmsd_to_ref_500ns!$M$2:$M$195) -> 2.1979 | K11: =_xlfn.XLOOKUP($A11,contact_features_all_40_500ns!$A$2:$A$195,contact_features_all_40_500ns!$E$2:$E$195) -> 2.8023967 | L11: =_xlfn.XLOOKUP($A11,contact_features_all_40_500ns!$A$2:$A$195,contact_features_all_40_500ns!$F$2:$F$195) -> 0.77621619 | M11: =_xlfn.XLOOKUP($A11,contact_features_all_40_500ns!$A$2:$A$195,contact_features_all_40_500ns!$H$2:$H$195) -> 1.555474 | N11: =_xlfn.XLOOKUP($A11,contact_features_all_40_500ns!$A$2:$A$195,contact_features_all_40_500ns!$I$2:$I$195) -> 0.61043078 | O11: =_xlfn.XLOOKUP($A11,contact_features_all_40_500ns!$A$2:$A$195,contact_features_all_40_500ns!$K$2:$K$195) -> 0.053965925 | P11: =_xlfn.XLOOKUP($A11,contact_features_all_40_500ns!$A$2:$A$195,contact_features_all_40_500ns!$L$2:$L$195) -> 0.22774723 | Q11: =_xlfn.XLOOKUP($A11,rmsf_single_residues_per_seq_50!$A$2:$A$195,rmsf_single_residues_per_seq_50!$E$2:$E$195) -> 2.838 | R11: =_xlfn.XLOOKUP($A11,rmsf_single_residues_per_seq_50!$A$2:$A$195,rmsf_single_residues_per_seq_50!$G$2:$G$195) -> 0.703 | S11: =_xlfn.XLOOKUP($A11,rmsf_single_residues_per_seq_50!$A$2:$A$195,rmsf_single_residues_per_seq_50!$H$2:$H$195) -> 0.605 | T11: =_xlfn.XLOOKUP($A11,rmsf_single_residues_per_seq_50!$A$2:$A$195,rmsf_single_residues_per_seq_50!$I$2:$I$195) -> 0.671 | U11: =_xlfn.XLOOKUP($A11,dw_scores_all_sequences_40_500n!$A$2:$A$195,dw_scores_all_sequences_40_500n!C$2:C$195) -> 0 | V11: =_xlfn.XLOOKUP($A11,dw_scores_all_sequences_40_500n!$A$2:$A$195,dw_scores_all_sequences_40_500n!D$2:D$195) -> 0 | W11: =_xlfn.XLOOKUP($A11,dw_scores_all_sequences_40_500n!$A$2:$A$195,dw_scores_all_sequences_40_500n!E$2:E$195) -> 0 | X11: =_xlfn.XLOOKUP($A11,dw_scores_all_sequences_40_500n!$A$2:$A$195,dw_scores_all_sequences_40_500n!F$2:F$195) -> 0 | Y11: =_xlfn.XLOOKUP($A11,dw_scores_all_sequences_40_500n!$A$2:$A$195,dw_scores_all_sequences_40_500n!G$2:G$195) -> 0 | Z11: =_xlfn.XLOOKUP($A11,dw_scores_all_sequences_40_500n!$A$2:$A$195,dw_scores_all_sequences_40_500n!H$2:H$195) -> 0 | AA11: =_xlfn.XLOOKUP($A11,dw_scores_all_sequences_40_500n!$A$2:$A$195,dw_scores_all_sequences_40_500n!I$2:I$195) -> 0 | AB11: =_xlfn.XLOOKUP($A11,dw_scores_all_sequences_40_500n!$A$2:$A$195,dw_scores_all_sequences_40_500n!J$2:J$195) -> 0 | ... IH11: =_xlfn.XLOOKUP($A11,dw_scores_all_sequences_40_500n!$A$2:$A$195,dw_scores_all_sequences_40_500n!HP$2:HP$195) -> 0
A12: pair_3098_binder | B12: 3098 | C12: binder | D12: =IF(C12="Binder", 1,0) -> 1 | E12: 0.3871 | F12: MASELTPEERSELKNSIAEFHTYQLDPGSCSSLHAQRIHAPPELVWSIVRRFDKPQTYAHFIKSCSVEQNFEMRVGCTRDLILISGLPANTMTVRLDILDDERRVTGVSIIGGEHRLTNYKSVTTVHRFEKENRIWTVVLKSYVVDMPEGNSEDDTRMIVDTGVKLLLQKLATVAEAMARN | G12: =_xlfn.XLOOKUP(A12,rmsf_ca_per_seq_summary_500ns!$A$2:$A$195,rmsf_ca_per_seq_summary_500ns!$C$2:$C$195) -> 0.35357 | H12: =_xlfn.XLOOKUP(A12,rmsf_ca_per_seq_summary_500ns!$A$2:$A$195,rmsf_ca_per_seq_summary_500ns!$D$2:$D$195) -> 0.06343 | I12: =_xlfn.XLOOKUP($A12,gate_latch_rmsd_to_ref_500ns!$A$2:$A$195,gate_latch_rmsd_to_ref_500ns!$I$2:$I$195) -> 2.5834 | J12: =_xlfn.XLOOKUP($A12,gate_latch_rmsd_to_ref_500ns!$A$2:$A$195,gate_latch_rmsd_to_ref_500ns!$M$2:$M$195) -> 3.2364 | K12: =_xlfn.XLOOKUP($A12,contact_features_all_40_500ns!$A$2:$A$195,contact_features_all_40_500ns!$E$2:$E$195) -> 2.091954 | L12: =_xlfn.XLOOKUP($A12,contact_features_all_40_500ns!$A$2:$A$195,contact_features_all_40_500ns!$F$2:$F$195) -> 0.67228471 | M12: =_xlfn.XLOOKUP($A12,contact_features_all_40_500ns!$A$2:$A$195,contact_features_all_40_500ns!$H$2:$H$195) -> 1.6677264 | N12: =_xlfn.XLOOKUP($A12,contact_features_all_40_500ns!$A$2:$A$195,contact_features_all_40_500ns!$I$2:$I$195) -> 0.92824193 | O12: =_xlfn.XLOOKUP($A12,contact_features_all_40_500ns!$A$2:$A$195,contact_features_all_40_500ns!$K$2:$K$195) -> 0.0070106791 | P12: =_xlfn.XLOOKUP($A12,contact_features_all_40_500ns!$A$2:$A$195,contact_features_all_40_500ns!$L$2:$L$195) -> 0.08343578 | Q12: =_xlfn.XLOOKUP($A12,rmsf_single_residues_per_seq_50!$A$2:$A$195,rmsf_single_residues_per_seq_50!$E$2:$E$195) -> 2.396 | R12: =_xlfn.XLOOKUP($A12,rmsf_single_residues_per_seq_50!$A$2:$A$195,rmsf_single_residues_per_seq_50!$G$2:$G$195) -> 1.353 | S12: =_xlfn.XLOOKUP($A12,rmsf_single_residues_per_seq_50!$A$2:$A$195,rmsf_single_residues_per_seq_50!$H$2:$H$195) -> 0.83 | T12: =_xlfn.XLOOKUP($A12,rmsf_single_residues_per_seq_50!$A$2:$A$195,rmsf_single_residues_per_seq_50!$I$2:$I$195) -> 2.313 | U12: =_xlfn.XLOOKUP($A12,dw_scores_all_sequences_40_500n!$A$2:$A$195,dw_scores_all_sequences_40_500n!C$2:C$195) -> 0 | V12: =_xlfn.XLOOKUP($A12,dw_scores_all_sequences_40_500n!$A$2:$A$195,dw_scores_all_sequences_40_500n!D$2:D$195) -> 0 | W12: =_xlfn.XLOOKUP($A12,dw_scores_all_sequences_40_500n!$A$2:$A$195,dw_scores_all_sequences_40_500n!E$2:E$195) -> 0 | X12: =_xlfn.XLOOKUP($A12,dw_scores_all_sequences_40_500n!$A$2:$A$195,dw_scores_all_sequences_40_500n!F$2:F$195) -> 0 | Y12: =_xlfn.XLOOKUP($A12,dw_scores_all_sequences_40_500n!$A$2:$A$195,dw_scores_all_sequences_40_500n!G$2:G$195) -> 0 | Z12: =_xlfn.XLOOKUP($A12,dw_scores_all_sequences_40_500n!$A$2:$A$195,dw_scores_all_sequences_40_500n!H$2:H$195) -> 0 | AA12: =_xlfn.XLOOKUP($A12,dw_scores_all_sequences_40_500n!$A$2:$A$195,dw_scores_all_sequences_40_500n!I$2:I$195) -> 0 | AB12: =_xlfn.XLOOKUP($A12,dw_scores_all_sequences_40_500n!$A$2:$A$195,dw_scores_all_sequences_40_500n!J$2:J$195) -> 0 | ... IH12: =_xlfn.XLOOKUP($A12,dw_scores_all_sequences_40_500n!$A$2:$A$195,dw_scores_all_sequences_40_500n!HP$2:HP$195) -> 0
A13: pair_3059_nb | B13: 3059 | C13: nonbinder | D13: =IF(C13="Binder", 1,0) -> 0 | F13: MASELTPEERSELKNSIAEFHTYQLDPGSCSSLHAQRIHAPPELVWSIVRRFDKPQTYVHFIKSCSVEQNFEMRVGCTRDLIAISGLPANTATERLDILDDERRVTGASVIGGEHRLTNLKWVTTVHRFEKENRIWTVVLRSYVVDMPEGNSEDDTRMHVDTLFKLGLQKLATVAEAMARN | G13: =_xlfn.XLOOKUP(A13,rmsf_ca_per_seq_summary_500ns!$A$2:$A$195,rmsf_ca_per_seq_summary_500ns!$C$2:$C$195) -> 0.396 | H13: =_xlfn.XLOOKUP(A13,rmsf_ca_per_seq_summary_500ns!$A$2:$A$195,rmsf_ca_per_seq_summary_500ns!$D$2:$D$195) -> 0.08626 | I13: =_xlfn.XLOOKUP($A13,gate_latch_rmsd_to_ref_500ns!$A$2:$A$195,gate_latch_rmsd_to_ref_500ns!$I$2:$I$195) -> 1.7708 | J13: =_xlfn.XLOOKUP($A13,gate_latch_rmsd_to_ref_500ns!$A$2:$A$195,gate_latch_rmsd_to_ref_500ns!$M$2:$M$195) -> 5.3601 | K13: =_xlfn.XLOOKUP($A13,contact_features_all_40_500ns!$A$2:$A$195,contact_features_all_40_500ns!$E$2:$E$195) -> 1.6560691 | L13: =_xlfn.XLOOKUP($A13,contact_features_all_40_500ns!$A$2:$A$195,contact_features_all_40_500ns!$F$2:$F$195) -> 0.80897165 | M13: =_xlfn.XLOOKUP($A13,contact_features_all_40_500ns!$A$2:$A$195,contact_features_all_40_500ns!$H$2:$H$195) -> 2.985245 | N13: =_xlfn.XLOOKUP($A13,contact_features_all_40_500ns!$A$2:$A$195,contact_features_all_40_500ns!$I$2:$I$195) -> 0.94213132 | O13: =_xlfn.XLOOKUP($A13,contact_features_all_40_500ns!$A$2:$A$195,contact_features_all_40_500ns!$K$2:$K$195) -> 0.16801174 | P13: =_xlfn.XLOOKUP($A13,contact_features_all_40_500ns!$A$2:$A$195,contact_features_all_40_500ns!$L$2:$L$195) -> 0.37453025 | Q13: =_xlfn.XLOOKUP($A13,rmsf_single_residues_per_seq_50!$A$2:$A$195,rmsf_single_residues_per_seq_50!$E$2:$E$195) -> 1.081 | R13: =_xlfn.XLOOKUP($A13,rmsf_single_residues_per_seq_50!$A$2:$A$195,rmsf_single_residues_per_seq_50!$G$2:$G$195) -> 0.638 | S13: =_xlfn.XLOOKUP($A13,rmsf_single_residues_per_seq_50!$A$2:$A$195,rmsf_single_residues_per_seq_50!$H$2:$H$195) -> 1.086 | T13: =_xlfn.XLOOKUP($A13,rmsf_single_residues_per_seq_50!$A$2:$A$195,rmsf_single_residues_per_seq_50!$I$2:$I$195) -> 1.538 | U13: =_xlfn.XLOOKUP($A13,dw_scores_all_sequences_40_500n!$A$2:$A$195,dw_scores_all_sequences_40_500n!C$2:C$195) -> 0 | V13: =_xlfn.XLOOKUP($A13,dw_scores_all_sequences_40_500n!$A$2:$A$195,dw_scores_all_sequences_40_500n!D$2:D$195) -> 0 | W13: =_xlfn.XLOOKUP($A13,dw_scores_all_sequences_40_500n!$A$2:$A$195,dw_scores_all_sequences_40_500n!E$2:E$195) -> 0 | X13: =_xlfn.XLOOKUP($A13,dw_scores_all_sequences_40_500n!$A$2:$A$195,dw_scores_all_sequences_40_500n!F$2:F$195) -> 0 | Y13: =_xlfn.XLOOKUP($A13,dw_scores_all_sequences_40_500n!$A$2:$A$195,dw_scores_all_sequences_40_500n!G$2:G$195) -> 0 | Z13: =_xlfn.XLOOKUP($A13,dw_scores_all_sequences_40_500n!$A$2:$A$195,dw_scores_all_sequences_40_500n!H$2:H$195) -> 0 | AA13: =_xlfn.XLOOKUP($A13,dw_scores_all_sequences_40_500n!$A$2:$A$195,dw_scores_all_sequences_40_500n!I$2:I$195) -> 0 | AB13: =_xlfn.XLOOKUP($A13,dw_scores_all_sequences_40_500n!$A$2:$A$195,dw_scores_all_sequences_40_500n!J$2:J$195) -> 0 | ... IH13: =_xlfn.XLOOKUP($A13,dw_scores_all_sequences_40_500n!$A$2:$A$195,dw_scores_all_sequences_40_500n!HP$2:HP$195) -> 0
A14: pair_3061_binder | B14: 3061 | C14: binder | D14: =IF(C14="Binder", 1,0) -> 1 | E14: 1.5 | F14: MASELTPEERSELKNSIAEFHTYQLDPGSCSSLHAQRIHAPPELVWSIVRRFDKPQTYVHFIKSCSVEQNFEMRVGCTRDDILISGLPANTMTVRLDILDDERRVTGASVIGGEHRVTNLKTVTTVHRFEKENRIWTVVLQSYVVDMPEGNSEDDTRMYVDTFVKLALQKLATVAEAMARN | G14: =_xlfn.XLOOKUP(A14,rmsf_ca_per_seq_summary_500ns!$A$2:$A$195,rmsf_ca_per_seq_summary_500ns!$C$2:$C$195) -> 0.34843 | H14: =_xlfn.XLOOKUP(A14,rmsf_ca_per_seq_summary_500ns!$A$2:$A$195,rmsf_ca_per_seq_summary_500ns!$D$2:$D$195) -> 0.05943 | I14: =_xlfn.XLOOKUP($A14,gate_latch_rmsd_to_ref_500ns!$A$2:$A$195,gate_latch_rmsd_to_ref_500ns!$I$2:$I$195) -> 1.1622 | J14: =_xlfn.XLOOKUP($A14,gate_latch_rmsd_to_ref_500ns!$A$2:$A$195,gate_latch_rmsd_to_ref_500ns!$M$2:$M$195) -> 2.3512 | K14: =_xlfn.XLOOKUP($A14,contact_features_all_40_500ns!$A$2:$A$195,contact_features_all_40_500ns!$E$2:$E$195) -> 3.9519035 | L14: =_xlfn.XLOOKUP($A14,contact_features_all_40_500ns!$A$2:$A$195,contact_features_all_40_500ns!$F$2:$F$195) -> 0.90565927 | M14: =_xlfn.XLOOKUP($A14,contact_features_all_40_500ns!$A$2:$A$195,contact_features_all_40_500ns!$H$2:$H$195) -> 1.3526535 | N14: =_xlfn.XLOOKUP($A14,contact_features_all_40_500ns!$A$2:$A$195,contact_features_all_40_500ns!$I$2:$I$195) -> 0.5082206 | O14: =_xlfn.XLOOKUP($A14,contact_features_all_40_500ns!$A$2:$A$195,contact_features_all_40_500ns!$K$2:$K$195) -> 0.0070921986 | P14: =_xlfn.XLOOKUP($A14,contact_features_all_40_500ns!$A$2:$A$195,contact_features_all_40_500ns!$L$2:$L$195) -> 0.083916025 | Q14: =_xlfn.XLOOKUP($A14,rmsf_single_residues_per_seq_50!$A$2:$A$195,rmsf_single_residues_per_seq_50!$E$2:$E$195) -> 1 | R14: =_xlfn.XLOOKUP($A14,rmsf_single_residues_per_seq_50!$A$2:$A$195,rmsf_single_residues_per_seq_50!$G$2:$G$195) -> 0.79 | S14: =_xlfn.XLOOKUP($A14,rmsf_single_residues_per_seq_50!$A$2:$A$195,rmsf_single_residues_per_seq_50!$H$2:$H$195) -> 0.694 | T14: =_xlfn.XLOOKUP($A14,rmsf_single_residues_per_seq_50!$A$2:$A$195,rmsf_single_residues_per_seq_50!$I$2:$I$195) -> 1.088 | U14: =_xlfn.XLOOKUP($A14,dw_scores_all_sequences_40_500n!$A$2:$A$195,dw_scores_all_sequences_40_500n!C$2:C$195) -> 0 | V14: =_xlfn.XLOOKUP($A14,dw_scores_all_sequences_40_500n!$A$2:$A$195,dw_scores_all_sequences_40_500n!D$2:D$195) -> 0 | W14: =_xlfn.XLOOKUP($A14,dw_scores_all_sequences_40_500n!$A$2:$A$195,dw_scores_all_sequences_40_500n!E$2:E$195) -> 0 | X14: =_xlfn.XLOOKUP($A14,dw_scores_all_sequences_40_500n!$A$2:$A$195,dw_scores_all_sequences_40_500n!F$2:F$195) -> 0 | Y14: =_xlfn.XLOOKUP($A14,dw_scores_all_sequences_40_500n!$A$2:$A$195,dw_scores_all_sequences_40_500n!G$2:G$195) -> 0 | Z14: =_xlfn.XLOOKUP($A14,dw_scores_all_sequences_40_500n!$A$2:$A$195,dw_scores_all_sequences_40_500n!H$2:H$195) -> 0 | AA14: =_xlfn.XLOOKUP($A14,dw_scores_all_sequences_40_500n!$A$2:$A$195,dw_scores_all_sequences_40_500n!I$2:I$195) -> 0 | AB14: =_xlfn.XLOOKUP($A14,dw_scores_all_sequences_40_500n!$A$2:$A$195,dw_scores_all_sequences_40_500n!J$2:J$195) -> 0 | ... IH14: =_xlfn.XLOOKUP($A14,dw_scores_all_sequences_40_500n!$A$2:$A$195,dw_scores_all_sequences_40_500n!HP$2:HP$195) -> 0
A15: pair_3062_binder | B15: 3062 | C15: binder | D15: =IF(C15="Binder", 1,0) -> 1 | E15: 0.8794 | F15: MASELTPEERSELKNSIAEFHTYQLDPGSCSSLHAQRIHAPPELVWSIVRRFDKPQTYVHFIKSCSVEQNFEMRVGCTRDDILISGLPANTMTVRLDILDDERRVTGASVIGGEHRVTNLKTVTTVHRFEKENRIWTVVLKSYVVDMPEGNSEDDTRMIVDTGVKLLLQKLATVAEAMARN | G15: =_xlfn.XLOOKUP(A15,rmsf_ca_per_seq_summary_500ns!$A$2:$A$195,rmsf_ca_per_seq_summary_500ns!$C$2:$C$195) -> 0.28986 | H15: =_xlfn.XLOOKUP(A15,rmsf_ca_per_seq_summary_500ns!$A$2:$A$195,rmsf_ca_per_seq_summary_500ns!$D$2:$D$195) -> 0.03864 | I15: =_xlfn.XLOOKUP($A15,gate_latch_rmsd_to_ref_500ns!$A$2:$A$195,gate_latch_rmsd_to_ref_500ns!$I$2:$I$195) -> 1.1222 | J15: =_xlfn.XLOOKUP($A15,gate_latch_rmsd_to_ref_500ns!$A$2:$A$195,gate_latch_rmsd_to_ref_500ns!$M$2:$M$195) -> 1.3849 | K15: =_xlfn.XLOOKUP($A15,contact_features_all_40_500ns!$A$2:$A$195,contact_features_all_40_500ns!$E$2:$E$195) -> 1.1824407 | L15: =_xlfn.XLOOKUP($A15,contact_features_all_40_500ns!$A$2:$A$195,contact_features_all_40_500ns!$F$2:$F$195) -> 0.53152801 | M15: =_xlfn.XLOOKUP($A15,contact_features_all_40_500ns!$A$2:$A$195,contact_features_all_40_500ns!$H$2:$H$195) -> 2.2677916 | N15: =_xlfn.XLOOKUP($A15,contact_features_all_40_500ns!$A$2:$A$195,contact_features_all_40_500ns!$I$2:$I$195) -> 0.96042607 | O15: =_xlfn.XLOOKUP($A15,contact_features_all_40_500ns!$A$2:$A$195,contact_features_all_40_500ns!$K$2:$K$195) -> 0.79603815 | P15: =_xlfn.XLOOKUP($A15,contact_features_all_40_500ns!$A$2:$A$195,contact_features_all_40_500ns!$L$2:$L$195) -> 0.40475766 | Q15: =_xlfn.XLOOKUP($A15,rmsf_single_residues_per_seq_50!$A$2:$A$195,rmsf_single_residues_per_seq_50!$E$2:$E$195) -> 1.786 | R15: =_xlfn.XLOOKUP($A15,rmsf_single_residues_per_seq_50!$A$2:$A$195,rmsf_single_residues_per_seq_50!$G$2:$G$195) -> 0.679 | S15: =_xlfn.XLOOKUP($A15,rmsf_single_residues_per_seq_50!$A$2:$A$195,rmsf_single_residues_per_seq_50!$H$2:$H$195) -> 0.609 | T15: =_xlfn.XLOOKUP($A15,rmsf_single_residues_per_seq_50!$A$2:$A$195,rmsf_single_residues_per_seq_50!$I$2:$I$195) -> 0.916 | U15: =_xlfn.XLOOKUP($A15,dw_scores_all_sequences_40_500n!$A$2:$A$195,dw_scores_all_sequences_40_500n!C$2:C$195) -> 0 | V15: =_xlfn.XLOOKUP($A15,dw_scores_all_sequences_40_500n!$A$2:$A$195,dw_scores_all_sequences_40_500n!D$2:D$195) -> 0 | W15: =_xlfn.XLOOKUP($A15,dw_scores_all_sequences_40_500n!$A$2:$A$195,dw_scores_all_sequences_40_500n!E$2:E$195) -> 0 | X15: =_xlfn.XLOOKUP($A15,dw_scores_all_sequences_40_500n!$A$2:$A$195,dw_scores_all_sequences_40_500n!F$2:F$195) -> 0 | Y15: =_xlfn.XLOOKUP($A15,dw_scores_all_sequences_40_500n!$A$2:$A$195,dw_scores_all_sequences_40_500n!G$2:G$195) -> 0 | Z15: =_xlfn.XLOOKUP($A15,dw_scores_all_sequences_40_500n!$A$2:$A$195,dw_scores_all_sequences_40_500n!H$2:H$195) -> 0 | AA15: =_xlfn.XLOOKUP($A15,dw_scores_all_sequences_40_500n!$A$2:$A$195,dw_scores_all_sequences_40_500n!I$2:I$195) -> 0 | AB15: =_xlfn.XLOOKUP($A15,dw_scores_all_sequences_40_500n!$A$2:$A$195,dw_scores_all_sequences_40_500n!J$2:J$195) -> 0 | ... IH15: =_xlfn.XLOOKUP($A15,dw_scores_all_sequences_40_500n!$A$2:$A$195,dw_scores_all_sequences_40_500n!HP$2:HP$195) -> 0
A16: pair_3063_binder | B16: 3063 | C16: binder | D16: =IF(C16="Binder", 1,0) -> 1 | E16: 0.8421 | F16: MASELTPEERSELKNSIAEFHTYQLDPGSCSSLHAQRIHAPPELVWSIVRRFDKPQTYAHFIKSCSVEQNFEMRVGCTRDDILISGLPANTMTVRLDILDDERRVTGASVIGGEHRVTNLKTVTTVHRFEKENRIWTVVLKSYVVDMPEGNSEDDTRMIMDTGIKLILQKLATVAEAMARN | G16: =_xlfn.XLOOKUP(A16,rmsf_ca_per_seq_summary_500ns!$A$2:$A$195,rmsf_ca_per_seq_summary_500ns!$C$2:$C$195) -> 0.35171 | H16: =_xlfn.XLOOKUP(A16,rmsf_ca_per_seq_summary_500ns!$A$2:$A$195,rmsf_ca_per_seq_summary_500ns!$D$2:$D$195) -> 0.06673 | I16: =_xlfn.XLOOKUP($A16,gate_latch_rmsd_to_ref_500ns!$A$2:$A$195,gate_latch_rmsd_to_ref_500ns!$I$2:$I$195) -> 3.8774 | J16: =_xlfn.XLOOKUP($A16,gate_latch_rmsd_to_ref_500ns!$A$2:$A$195,gate_latch_rmsd_to_ref_500ns!$M$2:$M$195) -> 3.7496 | K16: =_xlfn.XLOOKUP($A16,contact_features_all_40_500ns!$A$2:$A$195,contact_features_all_40_500ns!$E$2:$E$195) -> 2.254667 | L16: =_xlfn.XLOOKUP($A16,contact_features_all_40_500ns!$A$2:$A$195,contact_features_all_40_500ns!$F$2:$F$195) -> 1.1877071 | M16: =_xlfn.XLOOKUP($A16,contact_features_all_40_500ns!$A$2:$A$195,contact_features_all_40_500ns!$H$2:$H$195) -> 2.2905356 | N16: =_xlfn.XLOOKUP($A16,contact_features_all_40_500ns!$A$2:$A$195,contact_features_all_40_500ns!$I$2:$I$195) -> 0.74412627 | O16: =_xlfn.XLOOKUP($A16,contact_features_all_40_500ns!$A$2:$A$195,contact_features_all_40_500ns!$K$2:$K$195) -> 0.45414527 | P16: =_xlfn.XLOOKUP($A16,contact_features_all_40_500ns!$A$2:$A$195,contact_features_all_40_500ns!$L$2:$L$195) -> 0.49903769 | Q16: =_xlfn.XLOOKUP($A16,rmsf_single_residues_per_seq_50!$A$2:$A$195,rmsf_single_residues_per_seq_50!$E$2:$E$195) -> 1.65 | R16: =_xlfn.XLOOKUP($A16,rmsf_single_residues_per_seq_50!$A$2:$A$195,rmsf_single_residues_per_seq_50!$G$2:$G$195) -> 1.269 | S16: =_xlfn.XLOOKUP($A16,rmsf_single_residues_per_seq_50!$A$2:$A$195,rmsf_single_residues_per_seq_50!$H$2:$H$195) -> 0.991 | T16: =_xlfn.XLOOKUP($A16,rmsf_single_residues_per_seq_50!$A$2:$A$195,rmsf_single_residues_per_seq_50!$I$2:$I$195) -> 2.06 | U16: =_xlfn.XLOOKUP($A16,dw_scores_all_sequences_40_500n!$A$2:$A$195,dw_scores_all_sequences_40_500n!C$2:C$195) -> 0 | V16: =_xlfn.XLOOKUP($A16,dw_scores_all_sequences_40_500n!$A$2:$A$195,dw_scores_all_sequences_40_500n!D$2:D$195) -> 0 | W16: =_xlfn.XLOOKUP($A16,dw_scores_all_sequences_40_500n!$A$2:$A$195,dw_scores_all_sequences_40_500n!E$2:E$195) -> 0 | X16: =_xlfn.XLOOKUP($A16,dw_scores_all_sequences_40_500n!$A$2:$A$195,dw_scores_all_sequences_40_500n!F$2:F$195) -> 0 | Y16: =_xlfn.XLOOKUP($A16,dw_scores_all_sequences_40_500n!$A$2:$A$195,dw_scores_all_sequences_40_500n!G$2:G$195) -> 0 | Z16: =_xlfn.XLOOKUP($A16,dw_scores_all_sequences_40_500n!$A$2:$A$195,dw_scores_all_sequences_40_500n!H$2:H$195) -> 0.0261 | AA16: =_xlfn.XLOOKUP($A16,dw_scores_all_sequences_40_500n!$A$2:$A$195,dw_scores_all_sequences_40_500n!I$2:I$195) -> 0 | AB16: =_xlfn.XLOOKUP($A16,dw_scores_all_sequences_40_500n!$A$2:$A$195,dw_scores_all_sequences_40_500n!J$2:J$195) -> 0.0057 | ... IH16: =_xlfn.XLOOKUP($A16,dw_scores_all_sequences_40_500n!$A$2:$A$195,dw_scores_all_sequences_40_500n!HP$2:HP$195) -> 0
A17: pair_3066_binder | B17: 3066 | C17: binder | D17: =IF(C17="Binder", 1,0) -> 1 | E17: 0.7959 | F17: MASELTPEERSELKNSIAEFHTYQLDPGSCSSLHAQRIHAPPELVWSIVRRFDKPQTYVHFIKSCSVEQNFEMRVGCTRDDILISGLPANTMTLRLDILDDERRVTGASVIGGEHRVTNLKTVTTVHRFEKENRIWTVVLKSYVVDMPEGNSEDDTRMIMDTGIKLILQKLATVAEAMARN | G17: =_xlfn.XLOOKUP(A17,rmsf_ca_per_seq_summary_500ns!$A$2:$A$195,rmsf_ca_per_seq_summary_500ns!$C$2:$C$195) -> 0.29957 | H17: =_xlfn.XLOOKUP(A17,rmsf_ca_per_seq_summary_500ns!$A$2:$A$195,rmsf_ca_per_seq_summary_500ns!$D$2:$D$195) -> 0.05251 | I17: =_xlfn.XLOOKUP($A17,gate_latch_rmsd_to_ref_500ns!$A$2:$A$195,gate_latch_rmsd_to_ref_500ns!$I$2:$I$195) -> 2.7046 | J17: =_xlfn.XLOOKUP($A17,gate_latch_rmsd_to_ref_500ns!$A$2:$A$195,gate_latch_rmsd_to_ref_500ns!$M$2:$M$195) -> 1.6654 | K17: =_xlfn.XLOOKUP($A17,contact_features_all_40_500ns!$A$2:$A$195,contact_features_all_40_500ns!$E$2:$E$195) -> 1.3596641 | L17: =_xlfn.XLOOKUP($A17,contact_features_all_40_500ns!$A$2:$A$195,contact_features_all_40_500ns!$F$2:$F$195) -> 0.8321788 | M17: =_xlfn.XLOOKUP($A17,contact_features_all_40_500ns!$A$2:$A$195,contact_features_all_40_500ns!$H$2:$H$195) -> 2.3459689 | N17: =_xlfn.XLOOKUP($A17,contact_features_all_40_500ns!$A$2:$A$195,contact_features_all_40_500ns!$I$2:$I$195) -> 0.68830784 | O17: =_xlfn.XLOOKUP($A17,contact_features_all_40_500ns!$A$2:$A$195,contact_features_all_40_500ns!$K$2:$K$195) -> 0.32004565 | P17: =_xlfn.XLOOKUP($A17,contact_features_all_40_500ns!$A$2:$A$195,contact_features_all_40_500ns!$L$2:$L$195) -> 0.48634243 | Q17: =_xlfn.XLOOKUP($A17,rmsf_single_residues_per_seq_50!$A$2:$A$195,rmsf_single_residues_per_seq_50!$E$2:$E$195) -> 3.406 | R17: =_xlfn.XLOOKUP($A17,rmsf_single_residues_per_seq_50!$A$2:$A$195,rmsf_single_residues_per_seq_50!$G$2:$G$195) -> 1.081 | S17: =_xlfn.XLOOKUP($A17,rmsf_single_residues_per_seq_50!$A$2:$A$195,rmsf_single_residues_per_seq_50!$H$2:$H$195) -> 0.877 | T17: =_xlfn.XLOOKUP($A17,rmsf_single_residues_per_seq_50!$A$2:$A$195,rmsf_single_residues_per_seq_50!$I$2:$I$195) -> 0.704 | U17: =_xlfn.XLOOKUP($A17,dw_scores_all_sequences_40_500n!$A$2:$A$195,dw_scores_all_sequences_40_500n!C$2:C$195) -> 0 | V17: =_xlfn.XLOOKUP($A17,dw_scores_all_sequences_40_500n!$A$2:$A$195,dw_scores_all_sequences_40_500n!D$2:D$195) -> 0 | W17: =_xlfn.XLOOKUP($A17,dw_scores_all_sequences_40_500n!$A$2:$A$195,dw_scores_all_sequences_40_500n!E$2:E$195) -> 0 | X17: =_xlfn.XLOOKUP($A17,dw_scores_all_sequences_40_500n!$A$2:$A$195,dw_scores_all_sequences_40_500n!F$2:F$195) -> 0 | Y17: =_xlfn.XLOOKUP($A17,dw_scores_all_sequences_40_500n!$A$2:$A$195,dw_scores_all_sequences_40_500n!G$2:G$195) -> 0 | Z17: =_xlfn.XLOOKUP($A17,dw_scores_all_sequences_40_500n!$A$2:$A$195,dw_scores_all_sequences_40_500n!H$2:H$195) -> 0 | AA17: =_xlfn.XLOOKUP($A17,dw_scores_all_sequences_40_500n!$A$2:$A$195,dw_scores_all_sequences_40_500n!I$2:I$195) -> 0 | AB17: =_xlfn.XLOOKUP($A17,dw_scores_all_sequences_40_500n!$A$2:$A$195,dw_scores_all_sequences_40_500n!J$2:J$195) -> 0 | ... IH17: =_xlfn.XLOOKUP($A17,dw_scores_all_sequences_40_500n!$A$2:$A$195,dw_scores_all_sequences_40_500n!HP$2:HP$195) -> 0
A18: pair_3067_binder | B18: 3067 | C18: binder | D18: =IF(C18="Binder", 1,0) -> 1 | E18: 0.7921 | F18: MASELTPEERSELKNSIAEFHTYQLDPGSCSSLHAQRIHAPPELVWSIVRRFDKPQTYVHFIKSCSVEQNFEMRVGCTRDDILISGLPANTMTVRLDILDDERRVTGASVIGGEHRVTNLKTVTTVHRFEKENRIWTVVLKSYVVDMPEGNSEDDTRMILDTGYKLILQKLATVAEAMARN | G18: =_xlfn.XLOOKUP(A18,rmsf_ca_per_seq_summary_500ns!$A$2:$A$195,rmsf_ca_per_seq_summary_500ns!$C$2:$C$195) -> 0.47586 | H18: =_xlfn.XLOOKUP(A18,rmsf_ca_per_seq_summary_500ns!$A$2:$A$195,rmsf_ca_per_seq_summary_500ns!$D$2:$D$195) -> 0.13031 | I18: =_xlfn.XLOOKUP($A18,gate_latch_rmsd_to_ref_500ns!$A$2:$A$195,gate_latch_rmsd_to_ref_500ns!$I$2:$I$195) -> 1.7478 | J18: =_xlfn.XLOOKUP($A18,gate_latch_rmsd_to_ref_500ns!$A$2:$A$195,gate_latch_rmsd_to_ref_500ns!$M$2:$M$195) -> 2.8025 | K18: =_xlfn.XLOOKUP($A18,contact_features_all_40_500ns!$A$2:$A$195,contact_features_all_40_500ns!$E$2:$E$195) -> 1.94367 | L18: =_xlfn.XLOOKUP($A18,contact_features_all_40_500ns!$A$2:$A$195,contact_features_all_40_500ns!$F$2:$F$195) -> 0.27917532 | M18: =_xlfn.XLOOKUP($A18,contact_features_all_40_500ns!$A$2:$A$195,contact_features_all_40_500ns!$H$2:$H$195) -> 2.0079074 | N18: =_xlfn.XLOOKUP($A18,contact_features_all_40_500ns!$A$2:$A$195,contact_features_all_40_500ns!$I$2:$I$195) -> 0.70830088 | O18: =_xlfn.XLOOKUP($A18,contact_features_all_40_500ns!$A$2:$A$195,contact_features_all_40_500ns!$K$2:$K$195) -> 2.0102715 | P18: =_xlfn.XLOOKUP($A18,contact_features_all_40_500ns!$A$2:$A$195,contact_features_all_40_500ns!$L$2:$L$195) -> 0.14123845 | Q18: =_xlfn.XLOOKUP($A18,rmsf_single_residues_per_seq_50!$A$2:$A$195,rmsf_single_residues_per_seq_50!$E$2:$E$195) -> 1.958 | R18: =_xlfn.XLOOKUP($A18,rmsf_single_residues_per_seq_50!$A$2:$A$195,rmsf_single_residues_per_seq_50!$G$2:$G$195) -> 0.994 | S18: =_xlfn.XLOOKUP($A18,rmsf_single_residues_per_seq_50!$A$2:$A$195,rmsf_single_residues_per_seq_50!$H$2:$H$195) -> 0.835 | T18: =_xlfn.XLOOKUP($A18,rmsf_single_residues_per_seq_50!$A$2:$A$195,rmsf_single_residues_per_seq_50!$I$2:$I$195) -> 0.782 | U18: =_xlfn.XLOOKUP($A18,dw_scores_all_sequences_40_500n!$A$2:$A$195,dw_scores_all_sequences_40_500n!C$2:C$195) -> 0 | V18: =_xlfn.XLOOKUP($A18,dw_scores_all_sequences_40_500n!$A$2:$A$195,dw_scores_all_sequences_40_500n!D$2:D$195) -> 0 | W18: =_xlfn.XLOOKUP($A18,dw_scores_all_sequences_40_500n!$A$2:$A$195,dw_scores_all_sequences_40_500n!E$2:E$195) -> 0 | X18: =_xlfn.XLOOKUP($A18,dw_scores_all_sequences_40_500n!$A$2:$A$195,dw_scores_all_sequences_40_500n!F$2:F$195) -> 0 | Y18: =_xlfn.XLOOKUP($A18,dw_scores_all_sequences_40_500n!$A$2:$A$195,dw_scores_all_sequences_40_500n!G$2:G$195) -> 0 | Z18: =_xlfn.XLOOKUP($A18,dw_scores_all_sequences_40_500n!$A$2:$A$195,dw_scores_all_sequences_40_500n!H$2:H$195) -> 0 | AA18: =_xlfn.XLOOKUP($A18,dw_scores_all_sequences_40_500n!$A$2:$A$195,dw_scores_all_sequences_40_500n!I$2:I$195) -> 0 | AB18: =_xlfn.XLOOKUP($A18,dw_scores_all_sequences_40_500n!$A$2:$A$195,dw_scores_all_sequences_40_500n!J$2:J$195) -> 0 | ... IH18: =_xlfn.XLOOKUP($A18,dw_scores_all_sequences_40_500n!$A$2:$A$195,dw_scores_all_sequences_40_500n!HP$2:HP$195) -> 0
A19: pair_3068_binder | B19: 3068 | C19: binder | D19: =IF(C19="Binder", 1,0) -> 1 | E19: 0.7813 | F19: MASELTPEERSELKNSIAEFHTYQLDPGSCSSLHAQRIHAPPELVWSIVRRFDKPQTYVHFIKSCSVEQNFEMRVGCTRDDILISGLPANTMTVRLDILDDERRVTGASVIGGEHRVTNLKTVTTVHRFEKENRIWTVVLKSYVVDMPEGNSEDDTRMILDTGVKLILQKLATVAEAMARN | G19: =_xlfn.XLOOKUP(A19,rmsf_ca_per_seq_summary_500ns!$A$2:$A$195,rmsf_ca_per_seq_summary_500ns!$C$2:$C$195) -> 0.37529 | H19: =_xlfn.XLOOKUP(A19,rmsf_ca_per_seq_summary_500ns!$A$2:$A$195,rmsf_ca_per_seq_summary_500ns!$D$2:$D$195) -> 0.08904 | I19: =_xlfn.XLOOKUP($A19,gate_latch_rmsd_to_ref_500ns!$A$2:$A$195,gate_latch_rmsd_to_ref_500ns!$I$2:$I$195) -> 1.76 | J19: =_xlfn.XLOOKUP($A19,gate_latch_rmsd_to_ref_500ns!$A$2:$A$195,gate_latch_rmsd_to_ref_500ns!$M$2:$M$195) -> 2.2167 | K19: =_xlfn.XLOOKUP($A19,contact_features_all_40_500ns!$A$2:$A$195,contact_features_all_40_500ns!$E$2:$E$195) -> 2.1124969 | L19: =_xlfn.XLOOKUP($A19,contact_features_all_40_500ns!$A$2:$A$195,contact_features_all_40_500ns!$F$2:$F$195) -> 0.83098246 | M19: =_xlfn.XLOOKUP($A19,contact_features_all_40_500ns!$A$2:$A$195,contact_features_all_40_500ns!$H$2:$H$195) -> 2.6226461 | N19: =_xlfn.XLOOKUP($A19,contact_features_all_40_500ns!$A$2:$A$195,contact_features_all_40_500ns!$I$2:$I$195) -> 0.78120024 | O19: =_xlfn.XLOOKUP($A19,contact_features_all_40_500ns!$A$2:$A$195,contact_features_all_40_500ns!$K$2:$K$195) -> 0.028776392 | P19: =_xlfn.XLOOKUP($A19,contact_features_all_40_500ns!$A$2:$A$195,contact_features_all_40_500ns!$L$2:$L$195) -> 0.16717748 | Q19: =_xlfn.XLOOKUP($A19,rmsf_single_residues_per_seq_50!$A$2:$A$195,rmsf_single_residues_per_seq_50!$E$2:$E$195) -> 1.601 | R19: =_xlfn.XLOOKUP($A19,rmsf_single_residues_per_seq_50!$A$2:$A$195,rmsf_single_residues_per_seq_50!$G$2:$G$195) -> 0.777 | S19: =_xlfn.XLOOKUP($A19,rmsf_single_residues_per_seq_50!$A$2:$A$195,rmsf_single_residues_per_seq_50!$H$2:$H$195) -> 0.955 | T19: =_xlfn.XLOOKUP($A19,rmsf_single_residues_per_seq_50!$A$2:$A$195,rmsf_single_residues_per_seq_50!$I$2:$I$195) -> 0.677 | U19: =_xlfn.XLOOKUP($A19,dw_scores_all_sequences_40_500n!$A$2:$A$195,dw_scores_all_sequences_40_500n!C$2:C$195) -> 0 | V19: =_xlfn.XLOOKUP($A19,dw_scores_all_sequences_40_500n!$A$2:$A$195,dw_scores_all_sequences_40_500n!D$2:D$195) -> 0 | W19: =_xlfn.XLOOKUP($A19,dw_scores_all_sequences_40_500n!$A$2:$A$195,dw_scores_all_sequences_40_500n!E$2:E$195) -> 0 | X19: =_xlfn.XLOOKUP($A19,dw_scores_all_sequences_40_500n!$A$2:$A$195,dw_scores_all_sequences_40_500n!F$2:F$195) -> 0 | Y19: =_xlfn.XLOOKUP($A19,dw_scores_all_sequences_40_500n!$A$2:$A$195,dw_scores_all_sequences_40_500n!G$2:G$195) -> 0 | Z19: =_xlfn.XLOOKUP($A19,dw_scores_all_sequences_40_500n!$A$2:$A$195,dw_scores_all_sequences_40_500n!H$2:H$195) -> 0 | AA19: =_xlfn.XLOOKUP($A19,dw_scores_all_sequences_40_500n!$A$2:$A$195,dw_scores_all_sequences_40_500n!I$2:I$195) -> 0 | AB19: =_xlfn.XLOOKUP($A19,dw_scores_all_sequences_40_500n!$A$2:$A$195,dw_scores_all_sequences_40_500n!J$2:J$195) -> 0 | ... IH19: =_xlfn.XLOOKUP($A19,dw_scores_all_sequences_40_500n!$A$2:$A$195,dw_scores_all_sequences_40_500n!HP$2:HP$195) -> 0
